Workbook

Sheet README
A1: Auto-tagging HS football film: pricing and unit economics
A2: Built by hs-film-autotag/model/build_workbook.py on 2026-10-23
A4: Colour code: blue = hardcoded input or measurement; black = formula; green = link to another sheet; yellow fill = key assumption.
A5: Edit only blue cells on Inputs (and Benchmark if you re-run the benchmark). Everything else recalculates.
A7: Sheets
A8: Inputs: prices, usage, compute, storage, support, CAC, churn, fixed costs, seasonality.
A9: Benchmark: measured CPU timings on a CC BY-NC-SA 1080p high school game (no GPU in the test box).
A10: UnitEcon: cost per game, latency check, gross margin, LTV, CAC payback.
A11: Sensitivity: four two-way tables (price x compute, churn x CAC, detector x frames, price x cost base).
A12: Monthly: 48-month cash model with football seasonality and August billing.
A13: Market: bottom-up segment sizes.
A14: Adoption: outputs of the Monte Carlo adoption model (priors, not evidence).
A16: Main caveat: accuracy on core columns is not measured here. It is the largest unknown and is what the 90-day plan tests.

Sheet Inputs
A1: Inputs and assumptions (blue = input, yellow = key assumption, green = link)
A2: Change blue cells only. Every other sheet recalculates from here and from Benchmark.
A4: Pricing
A5: Price per program per season | B5: 900 | C5: $/program/season | D5: Model choice. Anchors: MaxPreps Advantage $600/team/season; Balltime HS $499/season; Hudl Silver+ with Assist $1,500/program/yr (hudl.com/pricing/high-school)
A6: Payment processing and collections | B6: 0.025 | C6: % of price | D6: Assumption: blend of card, ACH and paper checks
A8: Usage per program per season
A9: Own games broken down | B9: 10.5 | C9: games | D9: Assumption: UIL 10-game regular season plus average playoff run
A10: Opponent (scout) games broken down | B10: 15 | C10: games | D10: Assumption: ~1.5 opponent games/week; Hudl says coaches break down 2+ games/week in total
A11: Scrimmages, spring game | B11: 3 | C11: games | D11: Assumption
A12: Plays per game (both teams, incl. special teams) | B12: 140 | C12: plays | D12: Benchmark segment: 10 plays in 10 min; one program logged 615 offensive plays in 10 games (theteamroom.substack.com)
A13: Seconds of video per play clip | B13: 12 | C13: s | D13: Assumption: pre-snap to whistle
A14: Camera angles processed per play | B14: 1 | C14: angles | D14: Sideline only. Set 2 to also process end zone
A15: Share of games arriving as continuous (unclipped) film | B15: 0.3 | C15: % | D15: Assumption: tripod/Focus-style recordings vs Hudl cut-ups
A16: Length of continuous film per game | B16: 2.2 | C16: hours | D16: Benchmark source game ran 8,029 s (2.2 h) including halftime
A18: Compute (per play)
A19: Detector used | B19: yolo11s_640_tiled3 | C19: key | D19: Pick a key from the Benchmark table
A20: Detector frames per play | B20: 9 | C20: frames | D20: 3 pre-snap (formation, personnel) + 6 post-snap at 2 fps (play type, direction, result)
A21: Registration frames per play | B21: 6 | C21: frames | D21: Field lines at snap and at play end
A22: Orchestration, retries and I/O overhead | B22: 1.5 | C22: x | D22: Assumption
A23: vCPU-hour price | B23: =0.1785/4 -> 0.044625 | C23: $/vCPU-h | D23: AWS c7i.xlarge on-demand $0.1785/h for 4 vCPU, us-east-1 (calculator.holori.com, Jul 2026)
A24: GPU-hour price (T4, for the GPU alternative) | B24: 0.526 | C24: $/GPU-h | D24: AWS g4dn.xlarge on-demand, us-east-1 (calculator.holori.com); spot ~$0.23-0.26
A25: vCPUs per game job (fan-out) | B25: 32 | C25: vCPU | D25: Plays are independent, so a game splits across workers
A26: Coach upload bandwidth | B26: 20 | C26: Mbps | D26: Assumption; the real latency driver
A27: Video bitrate | B27: 4.01 | C27: Mbps | D27: Measured on the benchmark file (ffprobe)
A29: Storage and transfer
A30: Raw video retention after processing | B30: 14 | C30: days | D30: Design rule: delete raw video
A31: Object storage price | B31: 0.023 | C31: $/GB-month | D31: S3 Standard list price (assumption)
A32: Video served back to coaches per game | B32: 0 | C32: GB | D32: 0 if tags are written back to Hudl and film is watched there
A33: Egress price | B33: 0.09 | C33: $/GB | D33: Assumption: S3 internet egress first tier
A35: Support and quality assurance
A36: Support hours per program per season | B36: 4 | C36: hours | D36: Assumption
A37: Support cost per hour | B37: 40 | C37: $/hour | D37: Assumption: contractor rate
A38: Onboarding hours for a new program | B38: 3 | C38: hours | D38: Terminology mapping, first upload
A39: Human QA minutes per game | B39: 0 | C39: min/game | D39: Set 10-20 to model a human-in-the-loop guarantee
A40: QA cost per hour | B40: 20 | C40: $/hour | D40: Assumption
A42: Acquisition and retention
A43: Customer acquisition cost per new program | B43: 400 | C43: $ | D43: Assumption: founder-led; booth, travel and trial costs. Founder time not counted
A44: Annual churn | B44: 0.2 | C44: %/season | D44: Assumption; adoption sim draws 8-25% plus value-driven exits
A45: Discount rate | B45: 0.1 | C45: %/yr | D45: Assumption
A47: Fixed costs
...

Sheet Benchmark
A1: Measured compute benchmark (CPU, no GPU available in the test box)
A2: Footage: WHS Football vs Wakefield October 2, 2014 (segment 1500-2107 s), CC BY-NC-SA 4.0, 1920x1080 @ 29.97 fps. Source: https://archive.org/details/whs-football-vs-wakefield-october-2-2014
A4: Raw measurements (hardcoded = measured; see hs-film-autotag/bench/bench_pipeline.py)
A5: Segment length | B5: 606.83 | C5: s of video | D5: ffprobe duration of the downloaded segment
A6: Full 1080p H.264 decode, 1 thread: CPU time | B6: 111.072 | C6: CPU-s | D6: ffmpeg -benchmark utime+stime
A7: Full decode, all 4 threads: CPU time | B7: 122.62 | C7: CPU-s | D7: ffmpeg -benchmark utime+stime
A8: Full decode, all 4 threads: wall time | B8: 40.153 | C8: s | D8: ffmpeg -benchmark rtime
A9: Snap-signal processing (5 fps, 320x180, motion-compensated diff) | B9: 11.524 | C9: CPU-s | D9: Python/OpenCV time excluding decode
A10: Frames processed for snap signal | B10: 3034 | C10: frames
A11: Field-line detection per 1080p frame | B11: 23.59 | C11: ms | D11: HSV mask + Canny + HoughLinesP, mean of 40 frames
A12: Snaps in segment (manual count) | B12: 10 | C12: plays | D12: Counted from 2-second contact sheets
A13: Naive motion heuristic: true snaps found | B13: 6 | C13: plays | D13: 8 candidates returned
A14: Naive snap-heuristic recall | B14: =Benchmark!$B$13/Benchmark!$B$12 -> 0.6 | D14: Learned detector needed
A15: Pre-snap frames reviewed by eye | B15: 8 | C15: frames
A16: ...with a legible yard number | B16: 5 | C16: frames | D16: Others need camera-motion or game-state continuity
A17: ...with every player inside the frame | B17: 6 | C17: frames
A19: Derived rates
A20: Decode cost | B20: =Benchmark!$B$6/Benchmark!$B$5 -> 0.18303644 | C20: CPU-s per video-s | D20: 1080p, 4 Mbps
A21: Decode speed, 4 vCPU | B21: =Benchmark!$B$5/Benchmark!$B$8 -> 15.112943 | C21: x real time
A22: Snap-signal cost | B22: =Benchmark!$B$9/Benchmark!$B$5 -> 0.018990492 | C22: CPU-s per video-s
A23: Registration cost per frame | B23: =Benchmark!$B$11/1000 -> 0.02359 | C23: CPU-s per frame
A25: Detector (key) | B25: CPU ms/frame, 1 thread | C25: CPU ms/frame, 4 threads | D25: Persons found, mean of 8 pre-snap frames | E25: Published T4 GPU ms/frame | F25: Tiles | G25: License and note
A26: yolo11n_640 | B26: 108 | C26: 51.8 | E26: 1.5 | F26: 1 | G26: AGPL-3.0 (commercial use needs Ultralytics license). GPU: docs.ultralytics.com/models/yolo11
A27: yolo11s_640 | B27: 235.5 | C27: 96.2 | D27: 18 | E27: 2.5 | F27: 1 | G27: AGPL-3.0. GPU: Ultralytics T4 TensorRT10
A28: yolo11s_640_tiled3 | B28: 710.8 | C28: 281.4 | D28: 27.9 | E28: 2.5 | F28: 3 | G28: AGPL-3.0. 3 horizontal tiles, 15% overlap
A29: yolo11m_640 | B29: 635.6 | C29: 238.6 | E29: 4.7 | F29: 1 | G29: AGPL-3.0
A30: rfdetr_nano_384 | B30: 412.6 | C30: 197.6 | E30: 2.3 | F30: 1 | G30: Apache-2.0. GPU: rfdetr.roboflow.com (T4 TensorRT FP16)
A31: rfdetr_medium_576 | B31: 1074.6 | C31: 387.6 | D31: 26.5 | E31: 4.4 | F31: 1 | G31: Apache-2.0
A32: rfdetr_medium_576_tiled3 | B32: 3143 | C32: 1123.3 | D32: 40.2 | E32: 4.4 | F32: 3 | G32: Apache-2.0. 3 tiles
A34: Person counts include sideline players, coaches and officials; on-field filtering needs the field mask. Counts are a sanity check, not an accuracy measure.
A35: GPU column is vendor-published latency (not measured here) and feeds only the 'GPU alternative' line in UnitEcon.

Sheet UnitEcon
A1: Unit economics per game and per program-season
A3: Per game: compute and media
A4: Games per program per season | B4: =Inputs!$B$9+Inputs!$B$10+Inputs!$B$11 -> 28.5 | C4: games
A5: Video seconds processed per game | B5: =(1-Inputs!$B$15)*Inputs!$B$12*Inputs!$B$13*Inputs!$B$14+Inputs!$B$15*Inputs!$B$16*3600 -> 3552 | C5: s
A6: Decode cost (from Benchmark) | B6: =Benchmark!$B$20 -> 0.18303644 | C6: CPU-s per video-s
A7: Snap-signal cost (from Benchmark) | B7: =Benchmark!$B$22 -> 0.018990492 | C7: CPU-s per video-s
A8: Detector CPU-s per frame (selected model) | B8: =INDEX(Benchmark!$B$26:$B$32,MATCH(Inputs!$B$19,Benchmark!$A$26:$A$32,0))/1000 -> 0.7108 | C8: CPU-s per frame | D8: 1-thread measurement
A9: Registration CPU-s per frame | B9: =Benchmark!$B$23 -> 0.02359 | C9: CPU-s per frame
A10: CPU-s: decode | B10: =UnitEcon!$B$5*UnitEcon!$B$6 -> 650.14542 | C10: CPU-s
A11: CPU-s: play segmentation | B11: =UnitEcon!$B$5*UnitEcon!$B$7 -> 67.454226 | C11: CPU-s
A12: CPU-s: player detection | B12: =Inputs!$B$12*Inputs!$B$20*UnitEcon!$B$8 -> 895.608 | C12: CPU-s
A13: CPU-s: field registration | B13: =Inputs!$B$12*Inputs!$B$21*UnitEcon!$B$9 -> 19.8156 | C13: CPU-s
A14: CPU-s per game incl. overhead | B14: =(UnitEcon!$B$10+UnitEcon!$B$11+UnitEcon!$B$12+UnitEcon!$B$13)*Inputs!$B$22 -> 2449.5349 | C14: CPU-s
A15: CPU-s per play | B15: =UnitEcon!$B$14/Inputs!$B$12 -> 17.496678 | C15: CPU-s per play
A16: Compute cost per game (CPU only) | B16: =UnitEcon!$B$14/3600*Inputs!$B$23 -> 0.030364026 | C16: $/game | D16: Target: under $1
A17: Target check: compute under $1 per game | B17: =IF(UnitEcon!$B$16<1,"PASS","FAIL") -> PASS
A18: GPU alternative: detection on T4 (vendor latency) | B18: =Inputs!$B$12*Inputs!$B$20*INDEX(Benchmark!$E$26:$E$32,MATCH(Inputs!$B$19,Benchmark!$A$26:$A$32,0))*INDEX(Benchmark!$F$26:$F$32,MATCH(Inputs!$B$19,Benchmark!$A$26:$A$32,0))/1000/3600*Inputs!$B$24 -> 0.00138075 | C18: $/game | D18: Derived, not measured: no GPU in the test box
A19: Storage per game | B19: =UnitEcon!$B$5*Inputs!$B$27/8/1000*Inputs!$B$31*Inputs!$B$30/30 -> 0.019110056 | C19: $/game
A20: Egress per game | B20: =Inputs!$B$32*Inputs!$B$33 -> 0 | C20: $/game
A21: Compute + storage + egress per game | B21: =UnitEcon!$B$16+UnitEcon!$B$19+UnitEcon!$B$20 -> 0.049474082 | C21: $/game
A23: Latency check (target: breakdown within 10 min of upload)
A24: Processing wall time with fan-out | B24: =UnitEcon!$B$14/Inputs!$B$25/60 -> 1.2757994 | C24: minutes
A25: Upload time for the same video | B25: =UnitEcon!$B$5*Inputs!$B$27/Inputs!$B$26/60 -> 11.8696 | C25: minutes | D25: Happens before the 10-minute clock starts, but coaches feel it
A26: Target check: processing under 10 minutes | B26: =IF(UnitEcon!$B$24<=10,"PASS","FAIL") -> PASS
A28: Per program per season
A29: Revenue | B29: =Inputs!$B$5 -> 900 | C29: $
A30: Payment processing | B30: =UnitEcon!$B$29*Inputs!$B$6 -> 22.5 | C30: $
A31: Compute, storage, egress | B31: =UnitEcon!$B$21*UnitEcon!$B$4 -> 1.4100113 | C31: $
A32: Support | B32: =Inputs!$B$36*Inputs!$B$37 -> 160 | C32: $
A33: Human QA | B33: =Inputs!$B$39/60*Inputs!$B$40*UnitEcon!$B$4 -> 0 | C33: $
A34: Cost of revenue | B34: =UnitEcon!$B$30+UnitEcon!$B$31+UnitEcon!$B$32+UnitEcon!$B$33 -> 183.91001 | C34: $
A35: Gross profit | B35: =UnitEcon!$B$29-UnitEcon!$B$34 -> 716.08999 | C35: $
A36: Gross margin | B36: =IF(UnitEcon!$B$29>0,UnitEcon!$B$35/UnitEcon!$B$29,0) -> 0.79565554 | C36: %
A37: Compute share of revenue | B37: =IF(UnitEcon!$B$29>0,UnitEcon!$B$31/UnitEcon!$B$29,0) -> 0.0015666793 | C37: %
A39: Acquisition and lifetime value
A40: First-season contribution after CAC and onboarding | B40: =UnitEcon!$B$35-Inputs!$B$43-Inputs!$B$38*Inputs!$B$37 -> 196.08999 | C40: $
A41: Lifetime gross profit (LTV) | B41: =UnitEcon!$B$35*(1+Inputs!$B$45)/(Inputs!$B$45+Inputs!$B$44) -> 2625.6633 | C41: $ | D41: Seasonal periods; GP x (1+d)/(d+churn)
A42: LTV / CAC | B42: =IF(Inputs!$B$43>0,UnitEcon!$B$41/Inputs!$B$43,0) -> 6.5641582 | C42: x | D42: Rule of thumb: above 3x
A43: CAC payback | B43: =IF(UnitEcon!$B$35>0,Inputs!$B$43/UnitEcon!$B$35,0) -> 0.55858901 | C43: seasons
A44: Programs to cover fixed costs | B44: =(Inputs!$B$48*12+Inputs!$B$49)/UnitEcon!$B$35 -> 9.0770715 | C44: programs

Sheet Sensitivity
A1: Sensitivity tables (each cell is a live formula on Inputs/UnitEcon)
A3: Gross margin: price (columns) x compute cost multiplier (rows)
A4: Compute multiplier \ Price | B4: $300 | C4: $600 | D4: $900 | E4: $1,200 | F4: $1,800
A5: price -> | B5: 300 | C5: 600 | D5: 900 | E5: 1200 | F5: 1800
A6: 1 | B6: =(B$5*(1-Inputs!$B$6)-(UnitEcon!$B$16*$A6+UnitEcon!$B$19+UnitEcon!$B$20)*UnitEcon!$B$4-UnitEcon!$B$32-UnitEcon!$B$33)/B$5 -> 0.43696663 | C6: =(C$5*(1-Inputs!$B$6)-(UnitEcon!$B$16*$A6+UnitEcon!$B$19+UnitEcon!$B$20)*UnitEcon!$B$4-UnitEcon!$B$32-UnitEcon!$B$33)/C$5 -> 0.70598331 | D6: =(D$5*(1-Inputs!$B$6)-(UnitEcon!$B$16*$A6+UnitEcon!$B$19+UnitEcon!$B$20)*UnitEcon!$B$4-UnitEcon!$B$32-UnitEcon!$B$33)/D$5 -> 0.79565554 | E6: =(E$5*(1-Inputs!$B$6)-(UnitEcon!$B$16*$A6+UnitEcon!$B$19+UnitEcon!$B$20)*UnitEcon!$B$4-UnitEcon!$B$32-UnitEcon!$B$33)/E$5 -> 0.84049166 | F6: =(F$5*(1-Inputs!$B$6)-(UnitEcon!$B$16*$A6+UnitEcon!$B$19+UnitEcon!$B$20)*UnitEcon!$B$4-UnitEcon!$B$32-UnitEcon!$B$33)/F$5 -> 0.88532777
A7: 10 | B7: =(B$5*(1-Inputs!$B$6)-(UnitEcon!$B$16*$A7+UnitEcon!$B$19+UnitEcon!$B$20)*UnitEcon!$B$4-UnitEcon!$B$32-UnitEcon!$B$33)/B$5 -> 0.41100539 | C7: =(C$5*(1-Inputs!$B$6)-(UnitEcon!$B$16*$A7+UnitEcon!$B$19+UnitEcon!$B$20)*UnitEcon!$B$4-UnitEcon!$B$32-UnitEcon!$B$33)/C$5 -> 0.69300269 | D7: =(D$5*(1-Inputs!$B$6)-(UnitEcon!$B$16*$A7+UnitEcon!$B$19+UnitEcon!$B$20)*UnitEcon!$B$4-UnitEcon!$B$32-UnitEcon!$B$33)/D$5 -> 0.7870018 | E7: =(E$5*(1-Inputs!$B$6)-(UnitEcon!$B$16*$A7+UnitEcon!$B$19+UnitEcon!$B$20)*UnitEcon!$B$4-UnitEcon!$B$32-UnitEcon!$B$33)/E$5 -> 0.83400135 | F7: =(F$5*(1-Inputs!$B$6)-(UnitEcon!$B$16*$A7+UnitEcon!$B$19+UnitEcon!$B$20)*UnitEcon!$B$4-UnitEcon!$B$32-UnitEcon!$B$33)/F$5 -> 0.8810009
A8: 30 | B8: =(B$5*(1-Inputs!$B$6)-(UnitEcon!$B$16*$A8+UnitEcon!$B$19+UnitEcon!$B$20)*UnitEcon!$B$4-UnitEcon!$B$32-UnitEcon!$B$33)/B$5 -> 0.35331374 | C8: =(C$5*(1-Inputs!$B$6)-(UnitEcon!$B$16*$A8+UnitEcon!$B$19+UnitEcon!$B$20)*UnitEcon!$B$4-UnitEcon!$B$32-UnitEcon!$B$33)/C$5 -> 0.66415687 | D8: =(D$5*(1-Inputs!$B$6)-(UnitEcon!$B$16*$A8+UnitEcon!$B$19+UnitEcon!$B$20)*UnitEcon!$B$4-UnitEcon!$B$32-UnitEcon!$B$33)/D$5 -> 0.76777125 | E8: =(E$5*(1-Inputs!$B$6)-(UnitEcon!$B$16*$A8+UnitEcon!$B$19+UnitEcon!$B$20)*UnitEcon!$B$4-UnitEcon!$B$32-UnitEcon!$B$33)/E$5 -> 0.81957843 | F8: =(F$5*(1-Inputs!$B$6)-(UnitEcon!$B$16*$A8+UnitEcon!$B$19+UnitEcon!$B$20)*UnitEcon!$B$4-UnitEcon!$B$32-UnitEcon!$B$33)/F$5 -> 0.87138562
A9: 100 | B9: =(B$5*(1-Inputs!$B$6)-(UnitEcon!$B$16*$A9+UnitEcon!$B$19+UnitEcon!$B$20)*UnitEcon!$B$4-UnitEcon!$B$32-UnitEcon!$B$33)/B$5 -> 0.15139296 | C9: =(C$5*(1-Inputs!$B$6)-(UnitEcon!$B$16*$A9+UnitEcon!$B$19+UnitEcon!$B$20)*UnitEcon!$B$4-UnitEcon!$B$32-UnitEcon!$B$33)/C$5 -> 0.56319648 | D9: =(D$5*(1-Inputs!$B$6)-(UnitEcon!$B$16*$A9+UnitEcon!$B$19+UnitEcon!$B$20)*UnitEcon!$B$4-UnitEcon!$B$32-UnitEcon!$B$33)/D$5 -> 0.70046432 | E9: =(E$5*(1-Inputs!$B$6)-(UnitEcon!$B$16*$A9+UnitEcon!$B$19+UnitEcon!$B$20)*UnitEcon!$B$4-UnitEcon!$B$32-UnitEcon!$B$33)/E$5 -> 0.76909824 | F9: =(F$5*(1-Inputs!$B$6)-(UnitEcon!$B$16*$A9+UnitEcon!$B$19+UnitEcon!$B$20)*UnitEcon!$B$4-UnitEcon!$B$32-UnitEcon!$B$33)/F$5 -> 0.83773216
A10: 300 | B10: =(B$5*(1-Inputs!$B$6)-(UnitEcon!$B$16*$A10+UnitEcon!$B$19+UnitEcon!$B$20)*UnitEcon!$B$4-UnitEcon!$B$32-UnitEcon!$B$33)/B$5 -> -0.42552353 | C10: =(C$5*(1-Inputs!$B$6)-(UnitEcon!$B$16*$A10+UnitEcon!$B$19+UnitEcon!$B$20)*UnitEcon!$B$4-UnitEcon!$B$32-UnitEcon!$B$33)/C$5 -> 0.27473824 | D10: =(D$5*(1-Inputs!$B$6)-(UnitEcon!$B$16*$A10+UnitEcon!$B$19+UnitEcon!$B$20)*UnitEcon!$B$4-UnitEcon!$B$32-UnitEcon!$B$33)/D$5 -> 0.50815882 | E10: =(E$5*(1-Inputs!$B$6)-(UnitEcon!$B$16*$A10+UnitEcon!$B$19+UnitEcon!$B$20)*UnitEcon!$B$4-UnitEcon!$B$32-UnitEcon!$B$33)/E$5 -> 0.62486912 | F10: =(F$5*(1-Inputs!$B$6)-(UnitEcon!$B$16*$A10+UnitEcon!$B$19+UnitEcon!$B$20)*UnitEcon!$B$4-UnitEcon!$B$32-UnitEcon!$B$33)/F$5 -> 0.74157941
A11: Reading: compute would have to rise ~100x before it dents margin; support is the real cost.
A13: LTV / CAC: CAC (columns) x annual churn (rows)
A14: Churn \ CAC | B14: $200 | C14: $400 | D14: $800 | E14: $1,600 | F14: $3,200
A15: CAC -> | B15: 200 | C15: 400 | D15: 800 | E15: 1600 | F15: 3200
A16: 0.1 | B16: =UnitEcon!$B$35*(1+Inputs!$B$45)/(Inputs!$B$45+$A16)/B$15 -> 19.692475 | C16: =UnitEcon!$B$35*(1+Inputs!$B$45)/(Inputs!$B$45+$A16)/C$15 -> 9.8462373 | D16: =UnitEcon!$B$35*(1+Inputs!$B$45)/(Inputs!$B$45+$A16)/D$15 -> 4.9231187 | E16: =UnitEcon!$B$35*(1+Inputs!$B$45)/(Inputs!$B$45+$A16)/E$15 -> 2.4615593 | F16: =UnitEcon!$B$35*(1+Inputs!$B$45)/(Inputs!$B$45+$A16)/F$15 -> 1.2307797
A17: 0.2 | B17: =UnitEcon!$B$35*(1+Inputs!$B$45)/(Inputs!$B$45+$A17)/B$15 -> 13.128316 | C17: =UnitEcon!$B$35*(1+Inputs!$B$45)/(Inputs!$B$45+$A17)/C$15 -> 6.5641582 | D17: =UnitEcon!$B$35*(1+Inputs!$B$45)/(Inputs!$B$45+$A17)/D$15 -> 3.2820791 | E17: =UnitEcon!$B$35*(1+Inputs!$B$45)/(Inputs!$B$45+$A17)/E$15 -> 1.6410396 | F17: =UnitEcon!$B$35*(1+Inputs!$B$45)/(Inputs!$B$45+$A17)/F$15 -> 0.82051978
A18: 0.3 | B18: =UnitEcon!$B$35*(1+Inputs!$B$45)/(Inputs!$B$45+$A18)/B$15 -> 9.8462373 | C18: =UnitEcon!$B$35*(1+Inputs!$B$45)/(Inputs!$B$45+$A18)/C$15 -> 4.9231187 | D18: =UnitEcon!$B$35*(1+Inputs!$B$45)/(Inputs!$B$45+$A18)/D$15 -> 2.4615593 | E18: =UnitEcon!$B$35*(1+Inputs!$B$45)/(Inputs!$B$45+$A18)/E$15 -> 1.2307797 | F18: =UnitEcon!$B$35*(1+Inputs!$B$45)/(Inputs!$B$45+$A18)/F$15 -> 0.61538983
A19: 0.4 | B19: =UnitEcon!$B$35*(1+Inputs!$B$45)/(Inputs!$B$45+$A19)/B$15 -> 7.8769899 | C19: =UnitEcon!$B$35*(1+Inputs!$B$45)/(Inputs!$B$45+$A19)/C$15 -> 3.9384949 | D19: =UnitEcon!$B$35*(1+Inputs!$B$45)/(Inputs!$B$45+$A19)/D$15 -> 1.9692475 | E19: =UnitEcon!$B$35*(1+Inputs!$B$45)/(Inputs!$B$45+$A19)/E$15 -> 0.98462373 | F19: =UnitEcon!$B$35*(1+Inputs!$B$45)/(Inputs!$B$45+$A19)/F$15 -> 0.49231187
A20: 0.5 | B20: =UnitEcon!$B$35*(1+Inputs!$B$45)/(Inputs!$B$45+$A20)/B$15 -> 6.5641582 | C20: =UnitEcon!$B$35*(1+Inputs!$B$45)/(Inputs!$B$45+$A20)/C$15 -> 3.2820791 | D20: =UnitEcon!$B$35*(1+Inputs!$B$45)/(Inputs!$B$45+$A20)/D$15 -> 1.6410396 | E20: =UnitEcon!$B$35*(1+Inputs!$B$45)/(Inputs!$B$45+$A20)/E$15 -> 0.82051978 | F20: =UnitEcon!$B$35*(1+Inputs!$B$45)/(Inputs!$B$45+$A20)/F$15 -> 0.41025989
A23: Compute $ per game: detector (rows) x detector frames per play (columns)
A24: Detector \ frames per play | B24: 3 | C24: 9 | D24: 30 | E24: 60 | F24: 300
A25: frames -> | B25: 3 | C25: 9 | D25: 30 | E25: 60 | F25: 300
A26: yolo11n_640 | B26: =(UnitEcon!$B$10+UnitEcon!$B$11+UnitEcon!$B$13+Inputs!$B$12*B$25*INDEX(Benchmark!$B$26:$B$32,MATCH($A26,Benchmark!$A$26:$A$32,0))/1000)*Inputs!$B$22/3600*Inputs!$B$23 -> 0.014554727 | C26: =(UnitEcon!$B$10+UnitEcon!$B$11+UnitEcon!$B$13+Inputs!$B$12*C$25*INDEX(Benchmark!$B$26:$B$32,MATCH($A26,Benchmark!$A$26:$A$32,0))/1000)*Inputs!$B$22/3600*Inputs!$B$23 -> 0.016241552 | D26: =(UnitEcon!$B$10+UnitEcon!$B$11+UnitEcon!$B$13+Inputs!$B$12*D$25*INDEX(Benchmark!$B$26:$B$32,MATCH($A26,Benchmark!$A$26:$A$32,0))/1000)*Inputs!$B$22/3600*Inputs!$B$23 -> 0.02214544 | E26: =(UnitEcon!$B$10+UnitEcon!$B$11+UnitEcon!$B$13+Inputs!$B$12*E$25*INDEX(Benchmark!$B$26:$B$32,MATCH($A26,Benchmark!$A$26:$A$32,0))/1000)*Inputs!$B$22/3600*Inputs!$B$23 -> 0.030579565 | F26: =(UnitEcon!$B$10+UnitEcon!$B$11+UnitEcon!$B$13+Inputs!$B$12*F$25*INDEX(Benchmark!$B$26:$B$32,MATCH($A26,Benchmark!$A$26:$A$32,0))/1000)*Inputs!$B$22/3600*Inputs!$B$23 -> 0.098052565
A27: yolo11s_640 | B27: =(UnitEcon!$B$10+UnitEcon!$B$11+UnitEcon!$B$13+Inputs!$B$12*B$25*INDEX(Benchmark!$B$26:$B$32,MATCH($A27,Benchmark!$A$26:$A$32,0))/1000)*Inputs!$B$22/3600*Inputs!$B$23 -> 0.015550423 | C27: =(UnitEcon!$B$10+UnitEcon!$B$11+UnitEcon!$B$13+Inputs!$B$12*C$25*INDEX(Benchmark!$B$26:$B$32,MATCH($A27,Benchmark!$A$26:$A$32,0))/1000)*Inputs!$B$22/3600*Inputs!$B$23 -> 0.019228638 | D27: =(UnitEcon!$B$10+UnitEcon!$B$11+UnitEcon!$B$13+Inputs!$B$12*D$25*INDEX(Benchmark!$B$26:$B$32,MATCH($A27,Benchmark!$A$26:$A$32,0))/1000)*Inputs!$B$22/3600*Inputs!$B$23 -> 0.032102393 | E27: =(UnitEcon!$B$10+UnitEcon!$B$11+UnitEcon!$B$13+Inputs!$B$12*E$25*INDEX(Benchmark!$B$26:$B$32,MATCH($A27,Benchmark!$A$26:$A$32,0))/1000)*Inputs!$B$22/3600*Inputs!$B$23 -> 0.050493471 | F27: =(UnitEcon!$B$10+UnitEcon!$B$11+UnitEcon!$B$13+Inputs!$B$12*F$25*INDEX(Benchmark!$B$26:$B$32,MATCH($A27,Benchmark!$A$26:$A$32,0))/1000)*Inputs!$B$22/3600*Inputs!$B$23 -> 0.1976221
A28: yolo11s_640_tiled3 | B28: =(UnitEcon!$B$10+UnitEcon!$B$11+UnitEcon!$B$13+Inputs!$B$12*B$25*INDEX(Benchmark!$B$26:$B$32,MATCH($A28,Benchmark!$A$26:$A$32,0))/1000)*Inputs!$B$22/3600*Inputs!$B$23 -> 0.019262218 | C28: =(UnitEcon!$B$10+UnitEcon!$B$11+UnitEcon!$B$13+Inputs!$B$12*C$25*INDEX(Benchmark!$B$26:$B$32,MATCH($A28,Benchmark!$A$26:$A$32,0))/1000)*Inputs!$B$22/3600*Inputs!$B$23 -> 0.030364026 | D28: =(UnitEcon!$B$10+UnitEcon!$B$11+UnitEcon!$B$13+Inputs!$B$12*D$25*INDEX(Benchmark!$B$26:$B$32,MATCH($A28,Benchmark!$A$26:$A$32,0))/1000)*Inputs!$B$22/3600*Inputs!$B$23 -> 0.069220352 | E28: =(UnitEcon!$B$10+UnitEcon!$B$11+UnitEcon!$B$13+Inputs!$B$12*E$25*INDEX(Benchmark!$B$26:$B$32,MATCH($A28,Benchmark!$A$26:$A$32,0))/1000)*Inputs!$B$22/3600*Inputs!$B$23 -> 0.12472939 | F28: =(UnitEcon!$B$10+UnitEcon!$B$11+UnitEcon!$B$13+Inputs!$B$12*F$25*INDEX(Benchmark!$B$26:$B$32,MATCH($A28,Benchmark!$A$26:$A$32,0))/1000)*Inputs!$B$22/3600*Inputs!$B$23 -> 0.56880169
A29: yolo11m_640 | B29: =(UnitEcon!$B$10+UnitEcon!$B$11+UnitEcon!$B$13+Inputs!$B$12*B$25*INDEX(Benchmark!$B$26:$B$32,MATCH($A29,Benchmark!$A$26:$A$32,0))/1000)*Inputs!$B$22/3600*Inputs!$B$23 -> 0.018674953 | C29: =(UnitEcon!$B$10+UnitEcon!$B$11+UnitEcon!$B$13+Inputs!$B$12*C$25*INDEX(Benchmark!$B$26:$B$32,MATCH($A29,Benchmark!$A$26:$A$32,0))/1000)*Inputs!$B$22/3600*Inputs!$B$23 -> 0.028602231 | D29: =(UnitEcon!$B$10+UnitEcon!$B$11+UnitEcon!$B$13+Inputs!$B$12*D$25*INDEX(Benchmark!$B$26:$B$32,MATCH($A29,Benchmark!$A$26:$A$32,0))/1000)*Inputs!$B$22/3600*Inputs!$B$23 -> 0.063347702 | E29: =(UnitEcon!$B$10+UnitEcon!$B$11+UnitEcon!$B$13+Inputs!$B$12*E$25*INDEX(Benchmark!$B$26:$B$32,MATCH($A29,Benchmark!$A$26:$A$32,0))/1000)*Inputs!$B$22/3600*Inputs!$B$23 -> 0.11298409 | F29: =(UnitEcon!$B$10+UnitEcon!$B$11+UnitEcon!$B$13+Inputs!$B$12*F$25*INDEX(Benchmark!$B$26:$B$32,MATCH($A29,Benchmark!$A$26:$A$32,0))/1000)*Inputs!$B$22/3600*Inputs!$B$23 -> 0.51007519
A30: rfdetr_nano_384 | B30: =(UnitEcon!$B$10+UnitEcon!$B$11+UnitEcon!$B$13+Inputs!$B$12*B$25*INDEX(Benchmark!$B$26:$B$32,MATCH($A30,Benchmark!$A$26:$A$32,0))/1000)*Inputs!$B$22/3600*Inputs!$B$23 -> 0.016933463 | C30: =(UnitEcon!$B$10+UnitEcon!$B$11+UnitEcon!$B$13+Inputs!$B$12*C$25*INDEX(Benchmark!$B$26:$B$32,MATCH($A30,Benchmark!$A$26:$A$32,0))/1000)*Inputs!$B$22/3600*Inputs!$B$23 -> 0.023377759 | D30: =(UnitEcon!$B$10+UnitEcon!$B$11+UnitEcon!$B$13+Inputs!$B$12*D$25*INDEX(Benchmark!$B$26:$B$32,MATCH($A30,Benchmark!$A$26:$A$32,0))/1000)*Inputs!$B$22/3600*Inputs!$B$23 -> 0.045932796 | E30: =(UnitEcon!$B$10+UnitEcon!$B$11+UnitEcon!$B$13+Inputs!$B$12*E$25*INDEX(Benchmark!$B$26:$B$32,MATCH($A30,Benchmark!$A$26:$A$32,0))/1000)*Inputs!$B$22/3600*Inputs!$B$23 -> 0.078154277 | F30: =(UnitEcon!$B$10+UnitEcon!$B$11+UnitEcon!$B$13+Inputs!$B$12*F$25*INDEX(Benchmark!$B$26:$B$32,MATCH($A30,Benchmark!$A$26:$A$32,0))/1000)*Inputs!$B$22/3600*Inputs!$B$23 -> 0.33592613
A31: rfdetr_medium_576 | B31: =(UnitEcon!$B$10+UnitEcon!$B$11+UnitEcon!$B$13+Inputs!$B$12*B$25*INDEX(Benchmark!$B$26:$B$32,MATCH($A31,Benchmark!$A$26:$A$32,0))/1000)*Inputs!$B$22/3600*Inputs!$B$23 -> 0.022103269 | C31: =(UnitEcon!$B$10+UnitEcon!$B$11+UnitEcon!$B$13+Inputs!$B$12*C$25*INDEX(Benchmark!$B$26:$B$32,MATCH($A31,Benchmark!$A$26:$A$32,0))/1000)*Inputs!$B$22/3600*Inputs!$B$23 -> 0.038887178 | D31: =(UnitEcon!$B$10+UnitEcon!$B$11+UnitEcon!$B$13+Inputs!$B$12*D$25*INDEX(Benchmark!$B$26:$B$32,MATCH($A31,Benchmark!$A$26:$A$32,0))/1000)*Inputs!$B$22/3600*Inputs!$B$23 -> 0.097630858 | E31: =(UnitEcon!$B$10+UnitEcon!$B$11+UnitEcon!$B$13+Inputs!$B$12*E$25*INDEX(Benchmark!$B$26:$B$32,MATCH($A31,Benchmark!$A$26:$A$32,0))/1000)*Inputs!$B$22/3600*Inputs!$B$23 -> 0.1815504 | F31: =(UnitEcon!$B$10+UnitEcon!$B$11+UnitEcon!$B$13+Inputs!$B$12*F$25*INDEX(Benchmark!$B$26:$B$32,MATCH($A31,Benchmark!$A$26:$A$32,0))/1000)*Inputs!$B$22/3600*Inputs!$B$23 -> 0.85290675
A32: rfdetr_medium_576_tiled3 | B32: =(UnitEcon!$B$10+UnitEcon!$B$11+UnitEcon!$B$13+Inputs!$B$12*B$25*INDEX(Benchmark!$B$26:$B$32,MATCH($A32,Benchmark!$A$26:$A$32,0))/1000)*Inputs!$B$22/3600*Inputs!$B$23 -> 0.03825618 | C32: =(UnitEcon!$B$10+UnitEcon!$B$11+UnitEcon!$B$13+Inputs!$B$12*C$25*INDEX(Benchmark!$B$26:$B$32,MATCH($A32,Benchmark!$A$26:$A$32,0))/1000)*Inputs!$B$22/3600*Inputs!$B$23 -> 0.087345912 | D32: =(UnitEcon!$B$10+UnitEcon!$B$11+UnitEcon!$B$13+Inputs!$B$12*D$25*INDEX(Benchmark!$B$26:$B$32,MATCH($A32,Benchmark!$A$26:$A$32,0))/1000)*Inputs!$B$22/3600*Inputs!$B$23 -> 0.25915997 | E32: =(UnitEcon!$B$10+UnitEcon!$B$11+UnitEcon!$B$13+Inputs!$B$12*E$25*INDEX(Benchmark!$B$26:$B$32,MATCH($A32,Benchmark!$A$26:$A$32,0))/1000)*Inputs!$B$22/3600*Inputs!$B$23 -> 0.50460863 | F32: =(UnitEcon!$B$10+UnitEcon!$B$11+UnitEcon!$B$13+Inputs!$B$12*F$25*INDEX(Benchmark!$B$26:$B$32,MATCH($A32,Benchmark!$A$26:$A$32,0))/1000)*Inputs!$B$22/3600*Inputs!$B$23 -> 2.4681979
A33: 60 frames/play = full tracking at 10 fps for 6 s; 300 = 30 fps for 10 s. CPU only, on-demand prices.
A36: Programs needed to cover an annual cost base: price (columns) x annual cost (rows)
A37: Annual cost \ Price | B37: $300 | C37: $600 | D37: $900 | E37: $1,200 | F37: $1,800
A38: price -> | B38: 300 | C38: 600 | D38: 900 | E38: 1200 | F38: 1800
A39: 6500 | B39: =IF((B$38*(1-Inputs!$B$6)-UnitEcon!$B$31-UnitEcon!$B$32-UnitEcon!$B$33)>0,$A39/(B$38*(1-Inputs!$B$6)-UnitEcon!$B$31-UnitEcon!$B$32-UnitEcon!$B$33),0) -> 49.584259 | C39: =IF((C$38*(1-Inputs!$B$6)-UnitEcon!$B$31-UnitEcon!$B$32-UnitEcon!$B$33)>0,$A39/(C$38*(1-Inputs!$B$6)-UnitEcon!$B$31-UnitEcon!$B$32-UnitEcon!$B$33),0) -> 15.345027 | D39: =IF((D$38*(1-Inputs!$B$6)-UnitEcon!$B$31-UnitEcon!$B$32-UnitEcon!$B$33)>0,$A39/(D$38*(1-Inputs!$B$6)-UnitEcon!$B$31-UnitEcon!$B$32-UnitEcon!$B$33),0) -> 9.0770715 | E39: =IF((E$38*(1-Inputs!$B$6)-UnitEcon!$B$31-UnitEcon!$B$32-UnitEcon!$B$33)>0,$A39/(E$38*(1-Inputs!$B$6)-UnitEcon!$B$31-UnitEcon!$B$32-UnitEcon!$B$33),0) -> 6.4446406 | F39: =IF((F$38*(1-Inputs!$B$6)-UnitEcon!$B$31-UnitEcon!$B$32-UnitEcon!$B$33)>0,$A39/(F$38*(1-Inputs!$B$6)-UnitEcon!$B$31-UnitEcon!$B$32-UnitEcon!$B$33),0) -> 4.0788409
A40: 25000 | B40: =IF((B$38*(1-Inputs!$B$6)-UnitEcon!$B$31-UnitEcon!$B$32-UnitEcon!$B$33)>0,$A40/(B$38*(1-Inputs!$B$6)-UnitEcon!$B$31-UnitEcon!$B$32-UnitEcon!$B$33),0) -> 190.70869 | C40: =IF((C$38*(1-Inputs!$B$6)-UnitEcon!$B$31-UnitEcon!$B$32-UnitEcon!$B$33)>0,$A40/(C$38*(1-Inputs!$B$6)-UnitEcon!$B$31-UnitEcon!$B$32-UnitEcon!$B$33),0) -> 59.019336 | D40: =IF((D$38*(1-Inputs!$B$6)-UnitEcon!$B$31-UnitEcon!$B$32-UnitEcon!$B$33)>0,$A40/(D$38*(1-Inputs!$B$6)-UnitEcon!$B$31-UnitEcon!$B$32-UnitEcon!$B$33),0) -> 34.911813 | E40: =IF((E$38*(1-Inputs!$B$6)-UnitEcon!$B$31-UnitEcon!$B$32-UnitEcon!$B$33)>0,$A40/(E$38*(1-Inputs!$B$6)-UnitEcon!$B$31-UnitEcon!$B$32-UnitEcon!$B$33),0) -> 24.787079 | F40: =IF((F$38*(1-Inputs!$B$6)-UnitEcon!$B$31-UnitEcon!$B$32-UnitEcon!$B$33)>0,$A40/(F$38*(1-Inputs!$B$6)-UnitEcon!$B$31-UnitEcon!$B$32-UnitEcon!$B$33),0) -> 15.68785
A41: 100000 | B41: =IF((B$38*(1-Inputs!$B$6)-UnitEcon!$B$31-UnitEcon!$B$32-UnitEcon!$B$33)>0,$A41/(B$38*(1-Inputs!$B$6)-UnitEcon!$B$31-UnitEcon!$B$32-UnitEcon!$B$33),0) -> 762.83476 | C41: =IF((C$38*(1-Inputs!$B$6)-UnitEcon!$B$31-UnitEcon!$B$32-UnitEcon!$B$33)>0,$A41/(C$38*(1-Inputs!$B$6)-UnitEcon!$B$31-UnitEcon!$B$32-UnitEcon!$B$33),0) -> 236.07735 | D41: =IF((D$38*(1-Inputs!$B$6)-UnitEcon!$B$31-UnitEcon!$B$32-UnitEcon!$B$33)>0,$A41/(D$38*(1-Inputs!$B$6)-UnitEcon!$B$31-UnitEcon!$B$32-UnitEcon!$B$33),0) -> 139.64725 | E41: =IF((E$38*(1-Inputs!$B$6)-UnitEcon!$B$31-UnitEcon!$B$32-UnitEcon!$B$33)>0,$A41/(E$38*(1-Inputs!$B$6)-UnitEcon!$B$31-UnitEcon!$B$32-UnitEcon!$B$33),0) -> 99.148317 | F41: =IF((F$38*(1-Inputs!$B$6)-UnitEcon!$B$31-UnitEcon!$B$32-UnitEcon!$B$33)>0,$A41/(F$38*(1-Inputs!$B$6)-UnitEcon!$B$31-UnitEcon!$B$32-UnitEcon!$B$33),0) -> 62.751398
A42: 200000 | B42: =IF((B$38*(1-Inputs!$B$6)-UnitEcon!$B$31-UnitEcon!$B$32-UnitEcon!$B$33)>0,$A42/(B$38*(1-Inputs!$B$6)-UnitEcon!$B$31-UnitEcon!$B$32-UnitEcon!$B$33),0) -> 1525.6695 | C42: =IF((C$38*(1-Inputs!$B$6)-UnitEcon!$B$31-UnitEcon!$B$32-UnitEcon!$B$33)>0,$A42/(C$38*(1-Inputs!$B$6)-UnitEcon!$B$31-UnitEcon!$B$32-UnitEcon!$B$33),0) -> 472.15469 | D42: =IF((D$38*(1-Inputs!$B$6)-UnitEcon!$B$31-UnitEcon!$B$32-UnitEcon!$B$33)>0,$A42/(D$38*(1-Inputs!$B$6)-UnitEcon!$B$31-UnitEcon!$B$32-UnitEcon!$B$33),0) -> 279.29451 | E42: =IF((E$38*(1-Inputs!$B$6)-UnitEcon!$B$31-UnitEcon!$B$32-UnitEcon!$B$33)>0,$A42/(E$38*(1-Inputs!$B$6)-UnitEcon!$B$31-UnitEcon!$B$32-UnitEcon!$B$33),0) -> 198.29663 | F42: =IF((F$38*(1-Inputs!$B$6)-UnitEcon!$B$31-UnitEcon!$B$32-UnitEcon!$B$33)>0,$A42/(F$38*(1-Inputs!$B$6)-UnitEcon!$B$31-UnitEcon!$B$32-UnitEcon!$B$33),0) -> 125.5028
A43: 400000 | B43: =IF((B$38*(1-Inputs!$B$6)-UnitEcon!$B$31-UnitEcon!$B$32-UnitEcon!$B$33)>0,$A43/(B$38*(1-Inputs!$B$6)-UnitEcon!$B$31-UnitEcon!$B$32-UnitEcon!$B$33),0) -> 3051.339 | C43: =IF((C$38*(1-Inputs!$B$6)-UnitEcon!$B$31-UnitEcon!$B$32-UnitEcon!$B$33)>0,$A43/(C$38*(1-Inputs!$B$6)-UnitEcon!$B$31-UnitEcon!$B$32-UnitEcon!$B$33),0) -> 944.30938 | D43: =IF((D$38*(1-Inputs!$B$6)-UnitEcon!$B$31-UnitEcon!$B$32-UnitEcon!$B$33)>0,$A43/(D$38*(1-Inputs!$B$6)-UnitEcon!$B$31-UnitEcon!$B$32-UnitEcon!$B$33),0) -> 558.58901 | E43: =IF((E$38*(1-Inputs!$B$6)-UnitEcon!$B$31-UnitEcon!$B$32-UnitEcon!$B$33)>0,$A43/(E$38*(1-Inputs!$B$6)-UnitEcon!$B$31-UnitEcon!$B$32-UnitEcon!$B$33),0) -> 396.59327 | F43: =IF((F$38*(1-Inputs!$B$6)-UnitEcon!$B$31-UnitEcon!$B$32-UnitEcon!$B$33)>0,$A43/(F$38*(1-Inputs!$B$6)-UnitEcon!$B$31-UnitEcon!$B$32-UnitEcon!$B$33),0) -> 251.00559
A44: Rows: $6.5k = current fixed costs; $100k-$200k = one funded engineer; $400k = small team.

Sheet Monthly
A1: Monthly cash model, Jan 2027 - Dec 2030 (cash basis; annual billing in August)
A3: Month | B3: Year | C3: Month # | D3: Seasonality weight | E3: Paying programs (season) | F3: Pilot programs | G3: New paying programs | H3: Revenue (cash) | I3: Media COGS | J3: Support + QA | K3: Payment fees | L3: CAC | M3: Fixed costs | N3: Net cash flow | O3: Cumulative cash | Q3: Season lookup | R3: Paying programs
A4: 46388 | B4: =YEAR(A4) -> 2027 | C4: =MONTH(A4) -> 1 | D4: =INDEX(Inputs!$B$57:$B$68,C4) -> 0 | E4: =INDEX($R$4:$R$7,MATCH(B4,$Q$4:$Q$7,0)) -> 0 | F4: =IF(B4=2027,Inputs!$B$53,0) -> 8 | G4: =MAX(0,E4-IF(B4=2027,0,INDEX($R$4:$R$7,MATCH(B4-1,$Q$4:$Q$7,0)))*(1-Inputs!$B$44)) -> 0 | H4: =IF(C4=8,E4*Inputs!$B$5,0) -> 0 | I4: =(E4+F4)*UnitEcon!$B$31*D4 -> 0 | J4: =(E4+F4)*(UnitEcon!$B$32+UnitEcon!$B$33)*D4+IF(C4=8,G4*Inputs!$B$38*Inputs!$B$37,0) -> 0 | K4: =H4*Inputs!$B$6 -> 0 | L4: =IF(AND(C4>=4,C4<=7),G4*Inputs!$B$43/4,0) -> 0 | M4: =Inputs!$B$48+IF(C4=7,Inputs!$B$49,0)+IF(AND(B4=2027,C4=1),Inputs!$B$50,0) -> 3250 | N4: =H4-I4-J4-K4-L4-M4 -> -3250 | O4: =N4 -> -3250 | Q4: 2027 | R4: 0
A5: 46419 | B5: =YEAR(A5) -> 2027 | C5: =MONTH(A5) -> 2 | D5: =INDEX(Inputs!$B$57:$B$68,C5) -> 0 | E5: =INDEX($R$4:$R$7,MATCH(B5,$Q$4:$Q$7,0)) -> 0 | F5: =IF(B5=2027,Inputs!$B$53,0) -> 8 | G5: =MAX(0,E5-IF(B5=2027,0,INDEX($R$4:$R$7,MATCH(B5-1,$Q$4:$Q$7,0)))*(1-Inputs!$B$44)) -> 0 | H5: =IF(C5=8,E5*Inputs!$B$5,0) -> 0 | I5: =(E5+F5)*UnitEcon!$B$31*D5 -> 0 | J5: =(E5+F5)*(UnitEcon!$B$32+UnitEcon!$B$33)*D5+IF(C5=8,G5*Inputs!$B$38*Inputs!$B$37,0) -> 0 | K5: =H5*Inputs!$B$6 -> 0 | L5: =IF(AND(C5>=4,C5<=7),G5*Inputs!$B$43/4,0) -> 0 | M5: =Inputs!$B$48+IF(C5=7,Inputs!$B$49,0)+IF(AND(B5=2027,C5=1),Inputs!$B$50,0) -> 250 | N5: =H5-I5-J5-K5-L5-M5 -> -250 | O5: =O4+N5 -> -3500 | Q5: 2028 | R5: =INDEX(Adoption!$B$6:$D$9,2,Inputs!$B$54) -> 29
A6: 46447 | B6: =YEAR(A6) -> 2027 | C6: =MONTH(A6) -> 3 | D6: =INDEX(Inputs!$B$57:$B$68,C6) -> 0.02 | E6: =INDEX($R$4:$R$7,MATCH(B6,$Q$4:$Q$7,0)) -> 0 | F6: =IF(B6=2027,Inputs!$B$53,0) -> 8 | G6: =MAX(0,E6-IF(B6=2027,0,INDEX($R$4:$R$7,MATCH(B6-1,$Q$4:$Q$7,0)))*(1-Inputs!$B$44)) -> 0 | H6: =IF(C6=8,E6*Inputs!$B$5,0) -> 0 | I6: =(E6+F6)*UnitEcon!$B$31*D6 -> 0.22560181 | J6: =(E6+F6)*(UnitEcon!$B$32+UnitEcon!$B$33)*D6+IF(C6=8,G6*Inputs!$B$38*Inputs!$B$37,0) -> 25.6 | K6: =H6*Inputs!$B$6 -> 0 | L6: =IF(AND(C6>=4,C6<=7),G6*Inputs!$B$43/4,0) -> 0 | M6: =Inputs!$B$48+IF(C6=7,Inputs!$B$49,0)+IF(AND(B6=2027,C6=1),Inputs!$B$50,0) -> 250 | N6: =H6-I6-J6-K6-L6-M6 -> -275.8256 | O6: =O5+N6 -> -3775.8256 | Q6: 2029 | R6: =INDEX(Adoption!$B$6:$D$9,3,Inputs!$B$54) -> 49
A7: 46478 | B7: =YEAR(A7) -> 2027 | C7: =MONTH(A7) -> 4 | D7: =INDEX(Inputs!$B$57:$B$68,C7) -> 0.05 | E7: =INDEX($R$4:$R$7,MATCH(B7,$Q$4:$Q$7,0)) -> 0 | F7: =IF(B7=2027,Inputs!$B$53,0) -> 8 | G7: =MAX(0,E7-IF(B7=2027,0,INDEX($R$4:$R$7,MATCH(B7-1,$Q$4:$Q$7,0)))*(1-Inputs!$B$44)) -> 0 | H7: =IF(C7=8,E7*Inputs!$B$5,0) -> 0 | I7: =(E7+F7)*UnitEcon!$B$31*D7 -> 0.56400453 | J7: =(E7+F7)*(UnitEcon!$B$32+UnitEcon!$B$33)*D7+IF(C7=8,G7*Inputs!$B$38*Inputs!$B$37,0) -> 64 | K7: =H7*Inputs!$B$6 -> 0 | L7: =IF(AND(C7>=4,C7<=7),G7*Inputs!$B$43/4,0) -> 0 | M7: =Inputs!$B$48+IF(C7=7,Inputs!$B$49,0)+IF(AND(B7=2027,C7=1),Inputs!$B$50,0) -> 250 | N7: =H7-I7-J7-K7-L7-M7 -> -314.564 | O7: =O6+N7 -> -4090.3896 | Q7: 2030 | R7: =INDEX(Adoption!$B$6:$D$9,4,Inputs!$B$54) -> 71
A8: 46508 | B8: =YEAR(A8) -> 2027 | C8: =MONTH(A8) -> 5 | D8: =INDEX(Inputs!$B$57:$B$68,C8) -> 0.03 | E8: =INDEX($R$4:$R$7,MATCH(B8,$Q$4:$Q$7,0)) -> 0 | F8: =IF(B8=2027,Inputs!$B$53,0) -> 8 | G8: =MAX(0,E8-IF(B8=2027,0,INDEX($R$4:$R$7,MATCH(B8-1,$Q$4:$Q$7,0)))*(1-Inputs!$B$44)) -> 0 | H8: =IF(C8=8,E8*Inputs!$B$5,0) -> 0 | I8: =(E8+F8)*UnitEcon!$B$31*D8 -> 0.33840272 | J8: =(E8+F8)*(UnitEcon!$B$32+UnitEcon!$B$33)*D8+IF(C8=8,G8*Inputs!$B$38*Inputs!$B$37,0) -> 38.4 | K8: =H8*Inputs!$B$6 -> 0 | L8: =IF(AND(C8>=4,C8<=7),G8*Inputs!$B$43/4,0) -> 0 | M8: =Inputs!$B$48+IF(C8=7,Inputs!$B$49,0)+IF(AND(B8=2027,C8=1),Inputs!$B$50,0) -> 250 | N8: =H8-I8-J8-K8-L8-M8 -> -288.7384 | O8: =O7+N8 -> -4379.128
A9: 46539 | B9: =YEAR(A9) -> 2027 | C9: =MONTH(A9) -> 6 | D9: =INDEX(Inputs!$B$57:$B$68,C9) -> 0.01 | E9: =INDEX($R$4:$R$7,MATCH(B9,$Q$4:$Q$7,0)) -> 0 | F9: =IF(B9=2027,Inputs!$B$53,0) -> 8 | G9: =MAX(0,E9-IF(B9=2027,0,INDEX($R$4:$R$7,MATCH(B9-1,$Q$4:$Q$7,0)))*(1-Inputs!$B$44)) -> 0 | H9: =IF(C9=8,E9*Inputs!$B$5,0) -> 0 | I9: =(E9+F9)*UnitEcon!$B$31*D9 -> 0.11280091 | J9: =(E9+F9)*(UnitEcon!$B$32+UnitEcon!$B$33)*D9+IF(C9=8,G9*Inputs!$B$38*Inputs!$B$37,0) -> 12.8 | K9: =H9*Inputs!$B$6 -> 0 | L9: =IF(AND(C9>=4,C9<=7),G9*Inputs!$B$43/4,0) -> 0 | M9: =Inputs!$B$48+IF(C9=7,Inputs!$B$49,0)+IF(AND(B9=2027,C9=1),Inputs!$B$50,0) -> 250 | N9: =H9-I9-J9-K9-L9-M9 -> -262.9128 | O9: =O8+N9 -> -4642.0408
A10: 46569 | B10: =YEAR(A10) -> 2027 | C10: =MONTH(A10) -> 7 | D10: =INDEX(Inputs!$B$57:$B$68,C10) -> 0.01 | E10: =INDEX($R$4:$R$7,MATCH(B10,$Q$4:$Q$7,0)) -> 0 | F10: =IF(B10=2027,Inputs!$B$53,0) -> 8 | G10: =MAX(0,E10-IF(B10=2027,0,INDEX($R$4:$R$7,MATCH(B10-1,$Q$4:$Q$7,0)))*(1-Inputs!$B$44)) -> 0 | H10: =IF(C10=8,E10*Inputs!$B$5,0) -> 0 | I10: =(E10+F10)*UnitEcon!$B$31*D10 -> 0.11280091 | J10: =(E10+F10)*(UnitEcon!$B$32+UnitEcon!$B$33)*D10+IF(C10=8,G10*Inputs!$B$38*Inputs!$B$37,0) -> 12.8 | K10: =H10*Inputs!$B$6 -> 0 | L10: =IF(AND(C10>=4,C10<=7),G10*Inputs!$B$43/4,0) -> 0 | M10: =Inputs!$B$48+IF(C10=7,Inputs!$B$49,0)+IF(AND(B10=2027,C10=1),Inputs!$B$50,0) -> 3750 | N10: =H10-I10-J10-K10-L10-M10 -> -3762.9128 | O10: =O9+N10 -> -8404.9536
A11: 46600 | B11: =YEAR(A11) -> 2027 | C11: =MONTH(A11) -> 8 | D11: =INDEX(Inputs!$B$57:$B$68,C11) -> 0.1 | E11: =INDEX($R$4:$R$7,MATCH(B11,$Q$4:$Q$7,0)) -> 0 | F11: =IF(B11=2027,Inputs!$B$53,0) -> 8 | G11: =MAX(0,E11-IF(B11=2027,0,INDEX($R$4:$R$7,MATCH(B11-1,$Q$4:$Q$7,0)))*(1-Inputs!$B$44)) -> 0 | H11: =IF(C11=8,E11*Inputs!$B$5,0) -> 0 | I11: =(E11+F11)*UnitEcon!$B$31*D11 -> 1.1280091 | J11: =(E11+F11)*(UnitEcon!$B$32+UnitEcon!$B$33)*D11+IF(C11=8,G11*Inputs!$B$38*Inputs!$B$37,0) -> 128 | K11: =H11*Inputs!$B$6 -> 0 | L11: =IF(AND(C11>=4,C11<=7),G11*Inputs!$B$43/4,0) -> 0 | M11: =Inputs!$B$48+IF(C11=7,Inputs!$B$49,0)+IF(AND(B11=2027,C11=1),Inputs!$B$50,0) -> 250 | N11: =H11-I11-J11-K11-L11-M11 -> -379.12801 | O11: =O10+N11 -> -8784.0816
A12: 46631 | B12: =YEAR(A12) -> 2027 | C12: =MONTH(A12) -> 9 | D12: =INDEX(Inputs!$B$57:$B$68,C12) -> 0.25 | E12: =INDEX($R$4:$R$7,MATCH(B12,$Q$4:$Q$7,0)) -> 0 | F12: =IF(B12=2027,Inputs!$B$53,0) -> 8 | G12: =MAX(0,E12-IF(B12=2027,0,INDEX($R$4:$R$7,MATCH(B12-1,$Q$4:$Q$7,0)))*(1-Inputs!$B$44)) -> 0 | H12: =IF(C12=8,E12*Inputs!$B$5,0) -> 0 | I12: =(E12+F12)*UnitEcon!$B$31*D12 -> 2.8200227 | J12: =(E12+F12)*(UnitEcon!$B$32+UnitEcon!$B$33)*D12+IF(C12=8,G12*Inputs!$B$38*Inputs!$B$37,0) -> 320 | K12: =H12*Inputs!$B$6 -> 0 | L12: =IF(AND(C12>=4,C12<=7),G12*Inputs!$B$43/4,0) -> 0 | M12: =Inputs!$B$48+IF(C12=7,Inputs!$B$49,0)+IF(AND(B12=2027,C12=1),Inputs!$B$50,0) -> 250 | N12: =H12-I12-J12-K12-L12-M12 -> -572.82002 | O12: =O11+N12 -> -9356.9016
A13: 46661 | B13: =YEAR(A13) -> 2027 | C13: =MONTH(A13) -> 10 | D13: =INDEX(Inputs!$B$57:$B$68,C13) -> 0.27 | E13: =INDEX($R$4:$R$7,MATCH(B13,$Q$4:$Q$7,0)) -> 0 | F13: =IF(B13=2027,Inputs!$B$53,0) -> 8 | G13: =MAX(0,E13-IF(B13=2027,0,INDEX($R$4:$R$7,MATCH(B13-1,$Q$4:$Q$7,0)))*(1-Inputs!$B$44)) -> 0 | H13: =IF(C13=8,E13*Inputs!$B$5,0) -> 0 | I13: =(E13+F13)*UnitEcon!$B$31*D13 -> 3.0456245 | J13: =(E13+F13)*(UnitEcon!$B$32+UnitEcon!$B$33)*D13+IF(C13=8,G13*Inputs!$B$38*Inputs!$B$37,0) -> 345.6 | K13: =H13*Inputs!$B$6 -> 0 | L13: =IF(AND(C13>=4,C13<=7),G13*Inputs!$B$43/4,0) -> 0 | M13: =Inputs!$B$48+IF(C13=7,Inputs!$B$49,0)+IF(AND(B13=2027,C13=1),Inputs!$B$50,0) -> 250 | N13: =H13-I13-J13-K13-L13-M13 -> -598.64562 | O13: =O12+N13 -> -9955.5473
A14: 46692 | B14: =YEAR(A14) -> 2027 | C14: =MONTH(A14) -> 11 | D14: =INDEX(Inputs!$B$57:$B$68,C14) -> 0.2 | E14: =INDEX($R$4:$R$7,MATCH(B14,$Q$4:$Q$7,0)) -> 0 | F14: =IF(B14=2027,Inputs!$B$53,0) -> 8 | G14: =MAX(0,E14-IF(B14=2027,0,INDEX($R$4:$R$7,MATCH(B14-1,$Q$4:$Q$7,0)))*(1-Inputs!$B$44)) -> 0 | H14: =IF(C14=8,E14*Inputs!$B$5,0) -> 0 | I14: =(E14+F14)*UnitEcon!$B$31*D14 -> 2.2560181 | J14: =(E14+F14)*(UnitEcon!$B$32+UnitEcon!$B$33)*D14+IF(C14=8,G14*Inputs!$B$38*Inputs!$B$37,0) -> 256 | K14: =H14*Inputs!$B$6 -> 0 | L14: =IF(AND(C14>=4,C14<=7),G14*Inputs!$B$43/4,0) -> 0 | M14: =Inputs!$B$48+IF(C14=7,Inputs!$B$49,0)+IF(AND(B14=2027,C14=1),Inputs!$B$50,0) -> 250 | N14: =H14-I14-J14-K14-L14-M14 -> -508.25602 | O14: =O13+N14 -> -10463.803
A15: 46722 | B15: =YEAR(A15) -> 2027 | C15: =MONTH(A15) -> 12 | D15: =INDEX(Inputs!$B$57:$B$68,C15) -> 0.06 | E15: =INDEX($R$4:$R$7,MATCH(B15,$Q$4:$Q$7,0)) -> 0 | F15: =IF(B15=2027,Inputs!$B$53,0) -> 8 | G15: =MAX(0,E15-IF(B15=2027,0,INDEX($R$4:$R$7,MATCH(B15-1,$Q$4:$Q$7,0)))*(1-Inputs!$B$44)) -> 0 | H15: =IF(C15=8,E15*Inputs!$B$5,0) -> 0 | I15: =(E15+F15)*UnitEcon!$B$31*D15 -> 0.67680544 | J15: =(E15+F15)*(UnitEcon!$B$32+UnitEcon!$B$33)*D15+IF(C15=8,G15*Inputs!$B$38*Inputs!$B$37,0) -> 76.8 | K15: =H15*Inputs!$B$6 -> 0 | L15: =IF(AND(C15>=4,C15<=7),G15*Inputs!$B$43/4,0) -> 0 | M15: =Inputs!$B$48+IF(C15=7,Inputs!$B$49,0)+IF(AND(B15=2027,C15=1),Inputs!$B$50,0) -> 250 | N15: =H15-I15-J15-K15-L15-M15 -> -327.47681 | O15: =O14+N15 -> -10791.28
A16: 46753 | B16: =YEAR(A16) -> 2028 | C16: =MONTH(A16) -> 1 | D16: =INDEX(Inputs!$B$57:$B$68,C16) -> 0 | E16: =INDEX($R$4:$R$7,MATCH(B16,$Q$4:$Q$7,0)) -> 29 | F16: =IF(B16=2027,Inputs!$B$53,0) -> 0 | G16: =MAX(0,E16-IF(B16=2027,0,INDEX($R$4:$R$7,MATCH(B16-1,$Q$4:$Q$7,0)))*(1-Inputs!$B$44)) -> 29 | H16: =IF(C16=8,E16*Inputs!$B$5,0) -> 0 | I16: =(E16+F16)*UnitEcon!$B$31*D16 -> 0 | J16: =(E16+F16)*(UnitEcon!$B$32+UnitEcon!$B$33)*D16+IF(C16=8,G16*Inputs!$B$38*Inputs!$B$37,0) -> 0 | K16: =H16*Inputs!$B$6 -> 0 | L16: =IF(AND(C16>=4,C16<=7),G16*Inputs!$B$43/4,0) -> 0 | M16: =Inputs!$B$48+IF(C16=7,Inputs!$B$49,0)+IF(AND(B16=2027,C16=1),Inputs!$B$50,0) -> 250 | N16: =H16-I16-J16-K16-L16-M16 -> -250 | O16: =O15+N16 -> -11041.28
A17: 46784 | B17: =YEAR(A17) -> 2028 | C17: =MONTH(A17) -> 2 | D17: =INDEX(Inputs!$B$57:$B$68,C17) -> 0 | E17: =INDEX($R$4:$R$7,MATCH(B17,$Q$4:$Q$7,0)) -> 29 | F17: =IF(B17=2027,Inputs!$B$53,0) -> 0 | G17: =MAX(0,E17-IF(B17=2027,0,INDEX($R$4:$R$7,MATCH(B17-1,$Q$4:$Q$7,0)))*(1-Inputs!$B$44)) -> 29 | H17: =IF(C17=8,E17*Inputs!$B$5,0) -> 0 | I17: =(E17+F17)*UnitEcon!$B$31*D17 -> 0 | J17: =(E17+F17)*(UnitEcon!$B$32+UnitEcon!$B$33)*D17+IF(C17=8,G17*Inputs!$B$38*Inputs!$B$37,0) -> 0 | K17: =H17*Inputs!$B$6 -> 0 | L17: =IF(AND(C17>=4,C17<=7),G17*Inputs!$B$43/4,0) -> 0 | M17: =Inputs!$B$48+IF(C17=7,Inputs!$B$49,0)+IF(AND(B17=2027,C17=1),Inputs!$B$50,0) -> 250 | N17: =H17-I17-J17-K17-L17-M17 -> -250 | O17: =O16+N17 -> -11291.28
A18: 46813 | B18: =YEAR(A18) -> 2028 | C18: =MONTH(A18) -> 3 | D18: =INDEX(Inputs!$B$57:$B$68,C18) -> 0.02 | E18: =INDEX($R$4:$R$7,MATCH(B18,$Q$4:$Q$7,0)) -> 29 | F18: =IF(B18=2027,Inputs!$B$53,0) -> 0 | G18: =MAX(0,E18-IF(B18=2027,0,INDEX($R$4:$R$7,MATCH(B18-1,$Q$4:$Q$7,0)))*(1-Inputs!$B$44)) -> 29 | H18: =IF(C18=8,E18*Inputs!$B$5,0) -> 0 | I18: =(E18+F18)*UnitEcon!$B$31*D18 -> 0.81780657 | J18: =(E18+F18)*(UnitEcon!$B$32+UnitEcon!$B$33)*D18+IF(C18=8,G18*Inputs!$B$38*Inputs!$B$37,0) -> 92.8 | K18: =H18*Inputs!$B$6 -> 0 | L18: =IF(AND(C18>=4,C18<=7),G18*Inputs!$B$43/4,0) -> 0 | M18: =Inputs!$B$48+IF(C18=7,Inputs!$B$49,0)+IF(AND(B18=2027,C18=1),Inputs!$B$50,0) -> 250 | N18: =H18-I18-J18-K18-L18-M18 -> -343.61781 | O18: =O17+N18 -> -11634.898
A19: 46844 | B19: =YEAR(A19) -> 2028 | C19: =MONTH(A19) -> 4 | D19: =INDEX(Inputs!$B$57:$B$68,C19) -> 0.05 | E19: =INDEX($R$4:$R$7,MATCH(B19,$Q$4:$Q$7,0)) -> 29 | F19: =IF(B19=2027,Inputs!$B$53,0) -> 0 | G19: =MAX(0,E19-IF(B19=2027,0,INDEX($R$4:$R$7,MATCH(B19-1,$Q$4:$Q$7,0)))*(1-Inputs!$B$44)) -> 29 | H19: =IF(C19=8,E19*Inputs!$B$5,0) -> 0 | I19: =(E19+F19)*UnitEcon!$B$31*D19 -> 2.0445164 | J19: =(E19+F19)*(UnitEcon!$B$32+UnitEcon!$B$33)*D19+IF(C19=8,G19*Inputs!$B$38*Inputs!$B$37,0) -> 232 | K19: =H19*Inputs!$B$6 -> 0 | L19: =IF(AND(C19>=4,C19<=7),G19*Inputs!$B$43/4,0) -> 2900 | M19: =Inputs!$B$48+IF(C19=7,Inputs!$B$49,0)+IF(AND(B19=2027,C19=1),Inputs!$B$50,0) -> 250 | N19: =H19-I19-J19-K19-L19-M19 -> -3384.0445 | O19: =O18+N19 -> -15018.942
... A51: 47818 | B51: =YEAR(A51) -> 2030 | C51: =MONTH(A51) -> 12 | D51: =INDEX(Inputs!$B$57:$B$68,C51) -> 0.06 | E51: =INDEX($R$4:$R$7,MATCH(B51,$Q$4:$Q$7,0)) -> 71 | F51: =IF(B51=2027,Inputs!$B$53,0) -> 0 | G51: =MAX(0,E51-IF(B51=2027,0,INDEX($R$4:$R$7,MATCH(B51-1,$Q$4:$Q$7,0)))*(1-Inputs!$B$44)) -> 31.8 | H51: =IF(C51=8,E51*Inputs!$B$5,0) -> 0 | I51: =(E51+F51)*UnitEcon!$B$31*D51 -> 6.0066483 | J51: =(E51+F51)*(UnitEcon!$B$32+UnitEcon!$B$33)*D51+IF(C51=8,G51*Inputs!$B$38*Inputs!$B$37,0) -> 681.6 | K51: =H51*Inputs!$B$6 -> 0 | L51: =IF(AND(C51>=4,C51<=7),G51*Inputs!$B$43/4,0) -> 0 | M51: =Inputs!$B$48+IF(C51=7,Inputs!$B$49,0)+IF(AND(B51=2027,C51=1),Inputs!$B$50,0) -> 250 | N51: =H51-I51-J51-K51-L51-M51 -> -937.60665 | O51: =O50+N51 -> 31374.128
A53: Totals | H53: =SUM(H4:H51) -> 134100 | I53: =SUM(I4:I51) -> 221.37178 | J53: =SUM(J4:J51) -> 35512 | K53: =SUM(K4:K51) -> 3352.5 | L53: =SUM(L4:L51) -> 34640 | M53: =SUM(M4:M51) -> 29000 | N53: =SUM(N4:N51) -> 31374.128
A54: Lowest cumulative cash | O54: =MIN(O4:O51) -> -28202.987
A55: Founder time is unpaid and not in these numbers (about 1,000 hours a year at 20 h/week).

Sheet Market
A1: Market sizing (bottom-up, formulas)
A3: Segment | B3: Programs | C3: Price/season | D3: Revenue at 100% | E3: At 5% | F3: At 15% | G3: Source
A4: U.S. 11-player HS football (2024-25) | B4: 14269 | C4: =Inputs!$B$5 -> 900 | D4: =B4*C4 -> 12842100 | E4: =D4*0.05 -> 642105 | F4: =D4*0.15 -> 1926315 | G4: NFHS 2024-25 participation survey (nfhs.org)
A5: Texas UIL 11-man (2024-26) | B5: 1104 | C5: =Inputs!$B$5 -> 900 | D5: =B5*C5 -> 993600 | E5: =D5*0.05 -> 49680 | F5: =D5*0.15 -> 149040 | G5: UIL alignment PDF, counted by school
A6: Texas UIL six-man (2024-26) | B6: 154 | C6: 400 | D6: =B6*C6 -> 61600 | E6: =D6*0.05 -> 3080 | F6: =D6*0.15 -> 9240 | G6: UIL alignment PDF; six-man needs a separate model
A7: NCAA D2 + D3 + NAIA (2025) | B7: 496 | C7: 2500 | D7: =B7*C7 -> 1240000 | E7: =D7*0.05 -> 62000 | F7: =D7*0.15 -> 186000 | G7: Wikipedia 2025 season pages: 161 + 241 + 94; price assumption
A9: Top-down ceiling: all-sport Hudl spend if every school bought a department package
A10: Low package price (Dixie Heights HS, KY, 2022) | B10: 8700
A11: High package price (Tulsa PS, OK, 2026, per school) | B11: =139500/9 -> 15500
A12: Implied all-sport spend, low | B12: =B4*B10 -> 124140300
A13: Implied all-sport spend, high | B13: =B4*B11 -> 221169500

Sheet Adoption
A1: Adoption simulation output (hs-film-autotag/sim/adoption_sim.py, seed 20261023, 1,000 draws)
A2: Model of stated priors, not evidence. Texas UIL 11-man programs = 1104. Hardcoded values below are simulation outputs.
A4: Paying programs by season, base case ($900, 95% core accuracy)
A5: Season | B5: P10, Hudl never automates | C5: P50 | D5: P90 | E5: P50 if Hudl automates 2029 | F5: P50 if Hudl automates 2028
A6: 2027 | B6: 20 | C6: 38 | D6: 62 | E6: 40 | F6: 39
A7: 2028 | B7: 14 | C7: 29 | D7: 48 | E7: 29 | F7: 0
A8: 2029 | B8: 25 | C8: 49 | D8: 79 | E8: 0 | F8: 0
A9: 2030 | B9: 38 | C9: 71 | D9: 114 | E9: 0 | F9: 0
A10: 2027 counts are free-pilot uptake in the sim; Monthly uses Inputs' founder-capacity pilots instead.
A12: 2030 paying programs (P50) by price and accuracy, Hudl never automates
A13: Core-column accuracy \ Price | B13: $300 | C13: $600 | D13: $900 | E13: $1,200 | F13: $1,800
A14: 0.85 | B14: 29 | C14: 18 | D14: 10 | E14: 6 | F14: 2
A15: 0.9 | B15: 90 | C15: 56 | D15: 36 | E15: 23 | F15: 10
A16: 0.93 | B16: 138 | C16: 92 | D16: 61 | E16: 40 | F16: 19
A17: 0.95 | B17: 150 | C17: 104 | D17: 71 | E17: 49 | F17: 24
A18: 0.97 | B18: 157 | C18: 112 | D18: 78 | E18: 55 | F18: 28
A20: 2030 ARR (P50, $) = programs x price
A21: Core-column accuracy \ Price | B21: $300 | C21: $600 | D21: $900 | E21: $1,200 | F21: $1,800
A22: =A14 -> 0.85 | B22: =B14*300 -> 8700 | C22: =C14*600 -> 10800 | D22: =D14*900 -> 9000 | E22: =E14*1200 -> 7200 | F22: =F14*1800 -> 3600
A23: =A15 -> 0.9 | B23: =B15*300 -> 27000 | C23: =C15*600 -> 33600 | D23: =D15*900 -> 32400 | E23: =E15*1200 -> 27600 | F23: =F15*1800 -> 18000
A24: =A16 -> 0.93 | B24: =B16*300 -> 41400 | C24: =C16*600 -> 55200 | D24: =D16*900 -> 54900 | E24: =E16*1200 -> 48000 | F24: =F16*1800 -> 34200
A25: =A17 -> 0.95 | B25: =B17*300 -> 45000 | C25: =C17*600 -> 62400 | D25: =D17*900 -> 63900 | E25: =E17*1200 -> 58800 | F25: =F17*1800 -> 43200
A26: =A18 -> 0.97 | B26: =B18*300 -> 47100 | C26: =C18*600 -> 67200 | D26: =D18*900 -> 70200 | E26: =E18*1200 -> 66000 | F26: =F18*1800 -> 50400
A28: Same grid if Hudl ships automated football tagging in 2028: P50 programs
A29: Core-column accuracy \ Price | B29: $300 | C29: $600 | D29: $900 | E29: $1,200 | F29: $1,800
A30: 0.85 | B30: 1 | C30: 0 | D30: 0 | E30: 0 | F30: 0
A31: 0.9 | B31: 4 | C31: 1 | D31: 0 | E31: 0 | F31: 0
A32: 0.93 | B32: 5 | C32: 1 | D32: 0 | E32: 0 | F32: 0
A33: 0.95 | B33: 5 | C33: 1 | D33: 0 | E33: 0 | F33: 0
A34: 0.97 | B34: 5 | C34: 1 | D34: 0 | E34: 0 | F34: 0
